Traceback (most recent call last):
  File "/root/fraud_detection/run.py", line 2, in <module>
    from app.app import app
  File "/root/fraud_detection/app/app.py", line 4, in <module>
    import pandas as pd
ModuleNotFoundError: No module named 'pandas'
 * Serving Flask app 'app.app'
 * Debug mode: off
[31m[1mWARNING: This is a development server. Do not use it in a production deployment. Use a production WSGI server instead.[0m
 * Running on http://127.0.0.1:5000
[33mPress CTRL+C to quit[0m
 * Serving Flask app 'app.app'
 * Debug mode: off
Address already in use
Port 5000 is in use by another program. Either identify and stop that program, or start the server with a different port.
 * Serving Flask app 'app.app'
 * Debug mode: off
[31m[1mWARNING: This is a development server. Do not use it in a production deployment. Use a production WSGI server instead.[0m
 * Running on all addresses (0.0.0.0)
 * Running on http://127.0.0.1:5000
 * Running on http://82.180.154.192:5000
[33mPress CTRL+C to quit[0m
Traceback (most recent call last):
  File "/root/model_banking_system/run.py", line 1, in <module>
    from app import create_app, db
  File "/root/model_banking_system/app/__init__.py", line 2, in <module>
    from flask_sqlalchemy import SQLAlchemy
ModuleNotFoundError: No module named 'flask_sqlalchemy'
127.0.0.1 - - [08/Aug/2024 03:30:16] "[33mHEAD / HTTP/1.1[0m" 404 -
127.0.0.1 - - [08/Aug/2024 03:37:56] "[33mHEAD / HTTP/1.1[0m" 404 -
 * Serving Flask app 'app'
 * Debug mode: off
Address already in use
Port 5001 is in use by another program. Either identify and stop that program, or start the server with a different port.
82.180.154.192 - - [08/Aug/2024 03:44:25] "POST /webhook HTTP/1.1" 200 -
Traceback (most recent call last):
  File "/root/fraud_detection/run.py", line 1, in <module>
    from app.app import app
  File "/root/fraud_detection/app/app.py", line 4, in <module>
    import pandas as pd
  File "/root/fraud_detection/venv/lib/python3.10/site-packages/pandas/__init__.py", line 22, in <module>
    from pandas.compat import (
  File "/root/fraud_detection/venv/lib/python3.10/site-packages/pandas/compat/__init__.py", line 15, in <module>
    from pandas.compat.numpy import (
  File "/root/fraud_detection/venv/lib/python3.10/site-packages/pandas/compat/numpy/__init__.py", line 7, in <module>
    from pandas.util.version import Version
  File "/root/fraud_detection/venv/lib/python3.10/site-packages/pandas/util/__init__.py", line 1, in <module>
    from pandas.util._decorators import (  # noqa
  File "/root/fraud_detection/venv/lib/python3.10/site-packages/pandas/util/_decorators.py", line 14, in <module>
    from pandas._libs.properties import cache_readonly  # noqa
  File "/root/fraud_detection/venv/lib/python3.10/site-packages/pandas/_libs/__init__.py", line 13, in <module>
    from pandas._libs.interval import Interval
  File "pandas/_libs/interval.pyx", line 1, in init pandas._libs.interval
ValueError: numpy.dtype size changed, may indicate binary incompatibility. Expected 96 from C header, got 88 from PyObject
